Workbook

Sheet Formato de Pedido
O1: [ REPUESTOS ] ORDEN DE PEDIDO - MAKITA PERU S.A.
N2: Fecha de solicitud : | O2: =TODAY() -> 46220
N3: NRO. ORDEN DEL CLIENTE :
N4: Nro. Pedido SAP :
A6: DATOS DE FACTURACIÓN DEL CLIENTE :
B8: RUC CLIENTE :
B9: CLIENTE : | F9: Baterias XGT-LXT-CXT : | H9: Vigente
B10: DIRECCIÓN FISCAL : | F10: Cargadores XGT-LXT-CXT : | H10: Vigente
F11: Herramientas XGT-LXT-CXT : | H11: Vigente
B12: FORMA Y CONDICION DE PAGO : | F12: OPE y Aspiradoras DC : | H12: Vigente
B13: LETRAS
A15: DATOS DE ENTREGA : (Campo obligatorio)
B17: Despacho en Lima: | E17: Despacho por Agencia (Provincias) :
B18: Entregar en : | F18: Enviar por :
B19: Horario de recepción : | F19: Dirección de agencia :
B20: Persona de contacto : | F20: Destino en provincia :
A22: DETALLE DE PEDIDO :
A24: ITEM | B24: CÓDIGO | C24: DESCRIPCIÓN | D24: PRECIO LISTA UNITARIO | E24: CANT. | F24: DSCTO 1 | G24: DSCTO 2 | H24: DSCTO FINAL | I24: PRECIO SIN IGV | J24: SUB TOTAL SIN DCTOS(A) | K24: SOLES DSCTO 1 (B) | L24: SOLES DSCTO 2 (C) | M24: [STATUS STOCK] | N24: FAMILIA COMERCIAL | O24: Comentarios
A25: 1 | C25: =IFERROR(VLOOKUP(B25,'Lista de Productos'!A:B,2,FALSE)," ") | D25: =IFERROR(VLOOKUP(B25,Tabla_Hoja_1[#All],7,0),"") | H25: =IFERROR(FIXED(((1-((1-F25%)*(1-G25%)))*100),2)," ") -> 0.00 | I25: =IFERROR((E25*(D25*(1-H25%)))," ") | J25: =IFERROR((D25*E25), " ") | K25: =IFERROR((D25*F25%)*E25," ") | L25: =IFERROR(((J25-K25)*G25%), " ") | M25: =IFERROR(VLOOKUP(B25,Tabla_Hoja_1[#All],6,0)," ") | N25: =IFERROR(VLOOKUP(B25,'Lista de Productos'!A:C,3,FALSE)," ")
A26: 2 | C26: =IFERROR(VLOOKUP(B26,'Lista de Productos'!A:B,2,FALSE)," ") | D26: =IFERROR(VLOOKUP(B26,Tabla_Hoja_1[#All],7,0),"") | H26: =IFERROR(FIXED(((1-((1-F26%)*(1-G26%)))*100),2)," ") -> 0.00 | I26: =IFERROR((E26*(D26*(1-H26%)))," ") | J26: =IFERROR((D26*E26), " ") | K26: =IFERROR((D26*F26%)*E26," ") | L26: =IFERROR(((J26-K26)*G26%), " ") | M26: =IFERROR(VLOOKUP(B26,Tabla_Hoja_1[#All],6,0)," ") | N26: =IFERROR(VLOOKUP(B26,'Lista de Productos'!A:C,3,FALSE)," ")
A27: 3 | C27: =IFERROR(VLOOKUP(B27,'Lista de Productos'!A:B,2,FALSE)," ") | D27: =IFERROR(VLOOKUP(B27,Tabla_Hoja_1[#All],7,0),"") | H27: =IFERROR(FIXED(((1-((1-F27%)*(1-G27%)))*100),2)," ") -> 0.00 | I27: =IFERROR((E27*(D27*(1-H27%)))," ") | J27: =IFERROR((D27*E27), " ") | K27: =IFERROR((D27*F27%)*E27," ") | L27: =IFERROR(((J27-K27)*G27%), " ") | M27: =IFERROR(VLOOKUP(B27,Tabla_Hoja_1[#All],6,0)," ") | N27: =IFERROR(VLOOKUP(B27,'Lista de Productos'!A:C,3,FALSE)," ")
A28: 4 | C28: =IFERROR(VLOOKUP(B28,'Lista de Productos'!A:B,2,FALSE)," ") | D28: =IFERROR(VLOOKUP(B28,Tabla_Hoja_1[#All],7,0),"") | H28: =IFERROR(FIXED(((1-((1-F28%)*(1-G28%)))*100),2)," ") -> 0.00 | I28: =IFERROR((E28*(D28*(1-H28%)))," ") | J28: =IFERROR((D28*E28), " ") | K28: =IFERROR((D28*F28%)*E28," ") | L28: =IFERROR(((J28-K28)*G28%), " ") | M28: =IFERROR(VLOOKUP(B28,Tabla_Hoja_1[#All],6,0)," ") | N28: =IFERROR(VLOOKUP(B28,'Lista de Productos'!A:C,3,FALSE)," ")
A29: 5 | C29: =IFERROR(VLOOKUP(B29,'Lista de Productos'!A:B,2,FALSE)," ") | D29: =IFERROR(VLOOKUP(B29,Tabla_Hoja_1[#All],7,0),"") | H29: =IFERROR(FIXED(((1-((1-F29%)*(1-G29%)))*100),2)," ") -> 0.00 | I29: =IFERROR((E29*(D29*(1-H29%)))," ") | J29: =IFERROR((D29*E29), " ") | K29: =IFERROR((D29*F29%)*E29," ") | L29: =IFERROR(((J29-K29)*G29%), " ") | M29: =IFERROR(VLOOKUP(B29,Tabla_Hoja_1[#All],6,0)," ") | N29: =IFERROR(VLOOKUP(B29,'Lista de Productos'!A:C,3,FALSE)," ")
A30: 6 | C30: =IFERROR(VLOOKUP(B30,'Lista de Productos'!A:B,2,FALSE)," ") | D30: =IFERROR(VLOOKUP(B30,Tabla_Hoja_1[#All],7,0),"") | H30: =IFERROR(FIXED(((1-((1-F30%)*(1-G30%)))*100),2)," ") -> 0.00 | I30: =IFERROR((E30*(D30*(1-H30%)))," ") | J30: =IFERROR((D30*E30), " ") | K30: =IFERROR((D30*F30%)*E30," ") | L30: =IFERROR(((J30-K30)*G30%), " ") | M30: =IFERROR(VLOOKUP(B30,Tabla_Hoja_1[#All],6,0)," ") | N30: =IFERROR(VLOOKUP(B30,'Lista de Productos'!A:C,3,FALSE)," ")
A31: 7 | C31: =IFERROR(VLOOKUP(B31,'Lista de Productos'!A:B,2,FALSE)," ") | D31: =IFERROR(VLOOKUP(B31,Tabla_Hoja_1[#All],7,0),"") | H31: =IFERROR(FIXED(((1-((1-F31%)*(1-G31%)))*100),2)," ") -> 0.00 | I31: =IFERROR((E31*(D31*(1-H31%)))," ") | J31: =IFERROR((D31*E31), " ") | K31: =IFERROR((D31*F31%)*E31," ") | L31: =IFERROR(((J31-K31)*G31%), " ") | M31: =IFERROR(VLOOKUP(B31,Tabla_Hoja_1[#All],6,0)," ") | N31: =IFERROR(VLOOKUP(B31,'Lista de Productos'!A:C,3,FALSE)," ")
A32: 8 | C32: =IFERROR(VLOOKUP(B32,'Lista de Productos'!A:B,2,FALSE)," ") | D32: =IFERROR(VLOOKUP(B32,Tabla_Hoja_1[#All],7,0),"") | H32: =IFERROR(FIXED(((1-((1-F32%)*(1-G32%)))*100),2)," ") -> 0.00 | I32: =IFERROR((E32*(D32*(1-H32%)))," ") | J32: =IFERROR((D32*E32), " ") | K32: =IFERROR((D32*F32%)*E32," ") | L32: =IFERROR(((J32-K32)*G32%), " ") | M32: =IFERROR(VLOOKUP(B32,Tabla_Hoja_1[#All],6,0)," ") | N32: =IFERROR(VLOOKUP(B32,'Lista de Productos'!A:C,3,FALSE)," ")
A33: 9 | C33: =IFERROR(VLOOKUP(B33,'Lista de Productos'!A:B,2,FALSE)," ") | D33: =IFERROR(VLOOKUP(B33,Tabla_Hoja_1[#All],7,0),"") | H33: =IFERROR(FIXED(((1-((1-F33%)*(1-G33%)))*100),2)," ") -> 0.00 | I33: =IFERROR((E33*(D33*(1-H33%)))," ") | J33: =IFERROR((D33*E33), " ") | K33: =IFERROR((D33*F33%)*E33," ") | L33: =IFERROR(((J33-K33)*G33%), " ") | M33: =IFERROR(VLOOKUP(B33,Tabla_Hoja_1[#All],6,0)," ") | N33: =IFERROR(VLOOKUP(B33,'Lista de Productos'!A:C,3,FALSE)," ")
A34: 10 | C34: =IFERROR(VLOOKUP(B34,'Lista de Productos'!A:B,2,FALSE)," ") | D34: =IFERROR(VLOOKUP(B34,Tabla_Hoja_1[#All],7,0),"") | H34: =IFERROR(FIXED(((1-((1-F34%)*(1-G34%)))*100),2)," ") -> 0.00 | I34: =IFERROR((E34*(D34*(1-H34%)))," ") | J34: =IFERROR((D34*E34), " ") | K34: =IFERROR((D34*F34%)*E34," ") | L34: =IFERROR(((J34-K34)*G34%), " ") | M34: =IFERROR(VLOOKUP(B34,Tabla_Hoja_1[#All],6,0)," ") | N34: =IFERROR(VLOOKUP(B34,'Lista de Productos'!A:C,3,FALSE)," ")
A35: 11 | C35: =IFERROR(VLOOKUP(B35,'Lista de Productos'!A:B,2,FALSE)," ") | D35: =IFERROR(VLOOKUP(B35,Tabla_Hoja_1[#All],7,0),"") | H35: =IFERROR(FIXED(((1-((1-F35%)*(1-G35%)))*100),2)," ") -> 0.00 | I35: =IFERROR((E35*(D35*(1-H35%)))," ") | J35: =IFERROR((D35*E35), " ") | K35: =IFERROR((D35*F35%)*E35," ") | L35: =IFERROR(((J35-K35)*G35%), " ") | M35: =IFERROR(VLOOKUP(B35,Tabla_Hoja_1[#All],6,0)," ") | N35: =IFERROR(VLOOKUP(B35,'Lista de Productos'!A:C,3,FALSE)," ")
A36: 12 | C36: =IFERROR(VLOOKUP(B36,'Lista de Productos'!A:B,2,FALSE)," ") | D36: =IFERROR(VLOOKUP(B36,Tabla_Hoja_1[#All],7,0),"") | H36: =IFERROR(FIXED(((1-((1-F36%)*(1-G36%)))*100),2)," ") -> 0.00 | I36: =IFERROR((E36*(D36*(1-H36%)))," ") | J36: =IFERROR((D36*E36), " ") | K36: =IFERROR((D36*F36%)*E36," ") | L36: =IFERROR(((J36-K36)*G36%), " ") | M36: =IFERROR(VLOOKUP(B36,Tabla_Hoja_1[#All],6,0)," ") | N36: =IFERROR(VLOOKUP(B36,'Lista de Productos'!A:C,3,FALSE)," ")
... A49: 25 | C49: =IFERROR(VLOOKUP(B49,'Lista de Productos'!A:B,2,FALSE)," ") | D49: =IFERROR(VLOOKUP(B49,Tabla_Hoja_1[#All],7,0),"") | H49: =IFERROR(FIXED(((1-((1-F49%)*(1-G49%)))*100),2)," ") -> 0.00 | I49: =IFERROR((E49*(D49*(1-H49%)))," ") | J49: =IFERROR((D49*E49), " ") | K49: =IFERROR((D49*F49%)*E49," ") | L49: =IFERROR(((J49-K49)*G49%), " ") | M49: =IFERROR(VLOOKUP(B49,Tabla_Hoja_1[#All],6,0)," ") | N49: =IFERROR(VLOOKUP(B49,'Lista de Productos'!A:C,3,FALSE)," ")
B51: MERCHANDISING Y OBSEQUIOS PUBLICITARIOS | F51: SUB TOTAL SIN DCTOS (A) | I51: =+SUM(J25:J49) -> 0
B52: CÓDIGO | C52: DESCRIPCIÓN | D52: CANT. | F52: DESCUENTO 1 (B) | I52: =+SUM(K25:K49) -> 0 | N52: [STATUS STOCK]
F53: DESCUENTO 2 (C) | H53: =IFERROR((I53/(I51-I52)),"") | I53: =+SUM(L25:L49) -> 0 | N53: Rojo | O53: Agotado
F54: BASE IMPONIBLE | I54: =SUM(I25:I49) -> 0 | N54: Morado | O54: De 1 a 10 und
F55: IGV 18% | I55: =I54*0.18 -> 0 | N55: Amarillo | O55: De 11 a 50 und
F56: TOTAL CON IGV | I56: =+I54+I55 -> 0 | N56: Azul | O56: De 51 a 100 und
N57: Verde | O57: De 101 a más und
B58: REVISA MERCH VIGENTE AQUÍ | F58: SALDO A FAVOR DEL CLIENTE | G58: SALDO A FAVOR | I58: 0 | N58: *Consultar stock de COMBOS con ATC / Vendedor
A59: (1) Makita Perú S.A. no se responsabiliza por retrasos en la entrega si el cliente no completa correctamente los datos de entrega. | F59: MONTO A ABONAR | G59: SALDO A FAVOR | I59: =I56-I58 -> 0
...

Sheet Lista de Productos
A1: COD. ARTICULO | B1: DESCRIPCION | C1: FAMILIA SAP | D1: CATEGORIA SAP | E1: CATEGORIA | F1: Status | G1: LISTA GENERAL
A2: 001118100 | B2: CASQUILLO | C2: REPUESTOS | D2: REPUESTOS | E2: REPUESTOS | F2: Morado | G2: 6.14
A3: 001131150 | B3: VALVULA DE COMPRESION / DCS9010 | C3: REPUESTOS | D3: REPUESTOS | E3: REPUESTOS | F3: Rojo | G3: 85.33
A4: 001161020 | B4: JALADOR DE ARRANQUE / DCS7301 | C4: REPUESTOS | D4: REPUESTOS | E4: REPUESTOS | F4: Morado | G4: 17.7
A5: 001173060 | B5: TUERCA HEXAGONAL / VARIOS | C5: REPUESTOS | D5: REPUESTOS | E5: REPUESTOS | F5: Rojo | G5: 7.56
A6: 001182042 | B6: GUIA DE DISCO | C6: REPUESTOS | D6: REPUESTOS | E6: REPUESTOS | F6: Morado | G6: 13.26
A7: 001213160 | B7: TORNILLO TENSOR / UNIVERSAL | C7: REPUESTOS | D7: REPUESTOS | E7: REPUESTOS | F7: Morado | G7: 50.63
A8: 001213170 | B8: TUERCA MARIPOSA | C8: REPUESTOS | D8: REPUESTOS | E8: REPUESTOS | F8: Morado | G8: 48.5
A9: 0023705000 | B9: TUERCA INTERNA M5 / UNIVERSAL | C9: REPUESTOS | D9: REPUESTOS | E9: REPUESTOS | F9: Rojo | G9: 2.58
A10: 0043606200 | B10: TORNILLO M6X20 / UNIVERSAL | C10: REPUESTOS | D10: REPUESTOS | E10: REPUESTOS | F10: Morado | G10: 12.82
A11: 010038143 | B11: BOBINA DE ENCENDIDO / DCS7301 | C11: REPUESTOS | D11: REPUESTOS | E11: REPUESTOS | F11: Morado | G11: 657.5
A12: 010114039 | B12: JUEGO DE AMORTIGUADORES / DCS7301 | C12: REPUESTOS | D12: REPUESTOS | E12: REPUESTOS | F12: Morado | G12: 113.81
A13: 010114050 | B13: TAPA DE GASOLINA / DCS7301 | C13: REPUESTOS | D13: REPUESTOS | E13: REPUESTOS | F13: Rojo | G13: 27.14
... A16906: ZJ00000082 | B16906: JUEGO DE MEMBRANAS / VARIOS | C16906: REPUESTOS | D16906: REPUESTOS | E16906: REPUESTOS | F16906: Amarillo | G16906: 31.06
