Workbook

Sheet Formato de Pedido
P1: [ HERR Y ACC ] ORDEN DE PEDIDO - MAKITA PERU S.A.
O2: Fecha de solicitud : | P2: =TODAY() -> 46220
O3: NRO. ORDEN DEL CLIENTE :
O4: Nro. Pedido SAP :
A6: DATOS DE FACTURACIÓN DEL CLIENTE :
B8: RUC CLIENTE :
B9: CLIENTE : | F9: Baterias XGT-LXT-CXT : | I9: Vigente
B10: DIRECCIÓN FISCAL : | F10: Cargadores XGT-LXT-CXT : | I10: Vigente
F11: Herramientas XGT-LXT-CXT : | I11: Vigente
B12: FORMA Y CONDICION DE PAGO : | F12: OPE y Aspiradoras DC : | I12: Vigente
B13: LETRAS
A15: DATOS DE ENTREGA : (Campo obligatorio)
B17: Despacho en Lima: | E17: Despacho por Agencia (Provincias) :
B18: Entregar en : | F18: Enviar por :
B19: Horario de recepción : | F19: Dirección de agencia :
B20: Persona de contacto : | F20: Destino en provincia :
A22: DETALLE DE PEDIDO :
A24: ITEM | B24: CÓDIGO | C24: DESCRIPCIÓN | D24: PRECIO LISTA UNITARIO | E24: CANT. | F24: DSCTO 1 | G24: DSCTO 2 | I24: DSCTO FINAL | J24: PRECIO SIN IGV | K24: SUB TOTAL SIN DCTOS(A) | L24: SOLES DSCTO 1 (B) | M24: SOLES DSCTO 2 (C) | N24: [STATUS STOCK] | O24: FAMILIA COMERCIAL | P24: Comentarios
A25: 1 | C25: =IFERROR(VLOOKUP(B25,'Lista de Productos'!A:B,2,FALSE)," ") | D25: =IFERROR(VLOOKUP(B25,Tabla_Lista_de_productoss[],5,0),"") | I25: =IFERROR(FIXED(((1-((1-F25%)*(1-G25%)*(1-H25%)))*100),2)," ") -> 0.00 | J25: =IFERROR((E25*(D25*(1-I25%)))," ") | K25: =IFERROR((D25*E25), " ") | L25: =IFERROR((D25*F25%)*E25," ") | M25: =IFERROR(((K25-L25)*G25%), " ") | N25: =IFERROR(VLOOKUP(B25,'Lista de Productos'!A:D,4,FALSE)," ") | O25: =IFERROR(VLOOKUP(B25,'Lista de Productos'!A:C,3,FALSE)," ")
A26: 2 | C26: =IFERROR(VLOOKUP(B26,'Lista de Productos'!A:B,2,FALSE)," ") | D26: =IFERROR(VLOOKUP(B26,Tabla_Lista_de_productoss[],5,0),"") | I26: =IFERROR(FIXED(((1-((1-F26%)*(1-G26%)*(1-H26%)))*100),2)," ") -> 0.00 | J26: =IFERROR((E26*(D26*(1-I26%)))," ") | K26: =IFERROR((D26*E26), " ") | L26: =IFERROR((D26*F26%)*E26," ") | M26: =IFERROR(((K26-L26)*G26%), " ") | N26: =IFERROR(VLOOKUP(B26,'Lista de Productos'!A:D,4,FALSE)," ") | O26: =IFERROR(VLOOKUP(B26,'Lista de Productos'!A:C,3,FALSE)," ")
A27: 3 | C27: =IFERROR(VLOOKUP(B27,'Lista de Productos'!A:B,2,FALSE)," ") | D27: =IFERROR(VLOOKUP(B27,Tabla_Lista_de_productoss[],5,0),"") | I27: =IFERROR(FIXED(((1-((1-F27%)*(1-G27%)*(1-H27%)))*100),2)," ") -> 0.00 | J27: =IFERROR((E27*(D27*(1-I27%)))," ") | K27: =IFERROR((D27*E27), " ") | L27: =IFERROR((D27*F27%)*E27," ") | M27: =IFERROR(((K27-L27)*G27%), " ") | N27: =IFERROR(VLOOKUP(B27,'Lista de Productos'!A:D,4,FALSE)," ") | O27: =IFERROR(VLOOKUP(B27,'Lista de Productos'!A:C,3,FALSE)," ")
A28: 4 | C28: =IFERROR(VLOOKUP(B28,'Lista de Productos'!A:B,2,FALSE)," ") | D28: =IFERROR(VLOOKUP(B28,Tabla_Lista_de_productoss[],5,0),"") | I28: =IFERROR(FIXED(((1-((1-F28%)*(1-G28%)*(1-H28%)))*100),2)," ") -> 0.00 | J28: =IFERROR((E28*(D28*(1-I28%)))," ") | K28: =IFERROR((D28*E28), " ") | L28: =IFERROR((D28*F28%)*E28," ") | M28: =IFERROR(((K28-L28)*G28%), " ") | N28: =IFERROR(VLOOKUP(B28,'Lista de Productos'!A:D,4,FALSE)," ") | O28: =IFERROR(VLOOKUP(B28,'Lista de Productos'!A:C,3,FALSE)," ")
A29: 5 | C29: =IFERROR(VLOOKUP(B29,'Lista de Productos'!A:B,2,FALSE)," ") | D29: =IFERROR(VLOOKUP(B29,Tabla_Lista_de_productoss[],5,0),"") | I29: =IFERROR(FIXED(((1-((1-F29%)*(1-G29%)*(1-H29%)))*100),2)," ") -> 0.00 | J29: =IFERROR((E29*(D29*(1-I29%)))," ") | K29: =IFERROR((D29*E29), " ") | L29: =IFERROR((D29*F29%)*E29," ") | M29: =IFERROR(((K29-L29)*G29%), " ") | N29: =IFERROR(VLOOKUP(B29,'Lista de Productos'!A:D,4,FALSE)," ") | O29: =IFERROR(VLOOKUP(B29,'Lista de Productos'!A:C,3,FALSE)," ")
A30: 6 | C30: =IFERROR(VLOOKUP(B30,'Lista de Productos'!A:B,2,FALSE)," ") | D30: =IFERROR(VLOOKUP(B30,Tabla_Lista_de_productoss[],5,0),"") | I30: =IFERROR(FIXED(((1-((1-F30%)*(1-G30%)*(1-H30%)))*100),2)," ") -> 0.00 | J30: =IFERROR((E30*(D30*(1-I30%)))," ") | K30: =IFERROR((D30*E30), " ") | L30: =IFERROR((D30*F30%)*E30," ") | M30: =IFERROR(((K30-L30)*G30%), " ") | N30: =IFERROR(VLOOKUP(B30,'Lista de Productos'!A:D,4,FALSE)," ") | O30: =IFERROR(VLOOKUP(B30,'Lista de Productos'!A:C,3,FALSE)," ")
A31: 7 | C31: =IFERROR(VLOOKUP(B31,'Lista de Productos'!A:B,2,FALSE)," ") | D31: =IFERROR(VLOOKUP(B31,Tabla_Lista_de_productoss[],5,0),"") | I31: =IFERROR(FIXED(((1-((1-F31%)*(1-G31%)*(1-H31%)))*100),2)," ") -> 0.00 | J31: =IFERROR((E31*(D31*(1-I31%)))," ") | K31: =IFERROR((D31*E31), " ") | L31: =IFERROR((D31*F31%)*E31," ") | M31: =IFERROR(((K31-L31)*G31%), " ") | N31: =IFERROR(VLOOKUP(B31,'Lista de Productos'!A:D,4,FALSE)," ") | O31: =IFERROR(VLOOKUP(B31,'Lista de Productos'!A:C,3,FALSE)," ")
A32: 8 | C32: =IFERROR(VLOOKUP(B32,'Lista de Productos'!A:B,2,FALSE)," ") | D32: =IFERROR(VLOOKUP(B32,Tabla_Lista_de_productoss[],5,0),"") | I32: =IFERROR(FIXED(((1-((1-F32%)*(1-G32%)*(1-H32%)))*100),2)," ") -> 0.00 | J32: =IFERROR((E32*(D32*(1-I32%)))," ") | K32: =IFERROR((D32*E32), " ") | L32: =IFERROR((D32*F32%)*E32," ") | M32: =IFERROR(((K32-L32)*G32%), " ") | N32: =IFERROR(VLOOKUP(B32,'Lista de Productos'!A:D,4,FALSE)," ") | O32: =IFERROR(VLOOKUP(B32,'Lista de Productos'!A:C,3,FALSE)," ")
A33: 9 | C33: =IFERROR(VLOOKUP(B33,'Lista de Productos'!A:B,2,FALSE)," ") | D33: =IFERROR(VLOOKUP(B33,Tabla_Lista_de_productoss[],5,0),"") | I33: =IFERROR(FIXED(((1-((1-F33%)*(1-G33%)*(1-H33%)))*100),2)," ") -> 0.00 | J33: =IFERROR((E33*(D33*(1-I33%)))," ") | K33: =IFERROR((D33*E33), " ") | L33: =IFERROR((D33*F33%)*E33," ") | M33: =IFERROR(((K33-L33)*G33%), " ") | N33: =IFERROR(VLOOKUP(B33,'Lista de Productos'!A:D,4,FALSE)," ") | O33: =IFERROR(VLOOKUP(B33,'Lista de Productos'!A:C,3,FALSE)," ")
A34: 10 | C34: =IFERROR(VLOOKUP(B34,'Lista de Productos'!A:B,2,FALSE)," ") | D34: =IFERROR(VLOOKUP(B34,Tabla_Lista_de_productoss[],5,0),"") | I34: =IFERROR(FIXED(((1-((1-F34%)*(1-G34%)*(1-H34%)))*100),2)," ") -> 0.00 | J34: =IFERROR((E34*(D34*(1-I34%)))," ") | K34: =IFERROR((D34*E34), " ") | L34: =IFERROR((D34*F34%)*E34," ") | M34: =IFERROR(((K34-L34)*G34%), " ") | N34: =IFERROR(VLOOKUP(B34,'Lista de Productos'!A:D,4,FALSE)," ") | O34: =IFERROR(VLOOKUP(B34,'Lista de Productos'!A:C,3,FALSE)," ")
A35: 11 | C35: =IFERROR(VLOOKUP(B35,'Lista de Productos'!A:B,2,FALSE)," ") | D35: =IFERROR(VLOOKUP(B35,Tabla_Lista_de_productoss[],5,0),"") | I35: =IFERROR(FIXED(((1-((1-F35%)*(1-G35%)*(1-H35%)))*100),2)," ") -> 0.00 | J35: =IFERROR((E35*(D35*(1-I35%)))," ") | K35: =IFERROR((D35*E35), " ") | L35: =IFERROR((D35*F35%)*E35," ") | M35: =IFERROR(((K35-L35)*G35%), " ") | N35: =IFERROR(VLOOKUP(B35,'Lista de Productos'!A:D,4,FALSE)," ") | O35: =IFERROR(VLOOKUP(B35,'Lista de Productos'!A:C,3,FALSE)," ")
A36: 12 | C36: =IFERROR(VLOOKUP(B36,'Lista de Productos'!A:B,2,FALSE)," ") | D36: =IFERROR(VLOOKUP(B36,Tabla_Lista_de_productoss[],5,0),"") | I36: =IFERROR(FIXED(((1-((1-F36%)*(1-G36%)*(1-H36%)))*100),2)," ") -> 0.00 | J36: =IFERROR((E36*(D36*(1-I36%)))," ") | K36: =IFERROR((D36*E36), " ") | L36: =IFERROR((D36*F36%)*E36," ") | M36: =IFERROR(((K36-L36)*G36%), " ") | N36: =IFERROR(VLOOKUP(B36,'Lista de Productos'!A:D,4,FALSE)," ") | O36: =IFERROR(VLOOKUP(B36,'Lista de Productos'!A:C,3,FALSE)," ")
A37: 13 | C37: =IFERROR(VLOOKUP(B37,'Lista de Productos'!A:B,2,FALSE)," ") | D37: =IFERROR(VLOOKUP(B37,Tabla_Lista_de_productoss[],5,0),"") | I37: =IFERROR(FIXED(((1-((1-F37%)*(1-G37%)*(1-H37%)))*100),2)," ") -> 0.00 | J37: =IFERROR((E37*(D37*(1-I37%)))," ") | K37: =IFERROR((D37*E37), " ") | L37: =IFERROR((D37*F37%)*E37," ") | M37: =IFERROR(((K37-L37)*G37%), " ") | N37: =IFERROR(VLOOKUP(B37,'Lista de Productos'!A:D,4,FALSE)," ") | O37: =IFERROR(VLOOKUP(B37,'Lista de Productos'!A:C,3,FALSE)," ")
A38: 14 | C38: =IFERROR(VLOOKUP(B38,'Lista de Productos'!A:B,2,FALSE)," ") | D38: =IFERROR(VLOOKUP(B38,Tabla_Lista_de_productoss[],5,0),"") | I38: =IFERROR(FIXED(((1-((1-F38%)*(1-G38%)*(1-H38%)))*100),2)," ") -> 0.00 | J38: =IFERROR((E38*(D38*(1-I38%)))," ") | N38: =IFERROR(VLOOKUP(B38,'Lista de Productos'!A:D,4,FALSE)," ") | O38: =IFERROR(VLOOKUP(B38,'Lista de Productos'!A:C,3,FALSE)," ")
A39: 15 | C39: =IFERROR(VLOOKUP(B39,'Lista de Productos'!A:B,2,FALSE)," ") | D39: =IFERROR(VLOOKUP(B39,Tabla_Lista_de_productoss[],5,0),"") | I39: =IFERROR(FIXED(((1-((1-F39%)*(1-G39%)*(1-H39%)))*100),2)," ") -> 0.00 | J39: =IFERROR((E39*(D39*(1-I39%)))," ") | N39: =IFERROR(VLOOKUP(B39,'Lista de Productos'!A:D,4,FALSE)," ") | O39: =IFERROR(VLOOKUP(B39,'Lista de Productos'!A:C,3,FALSE)," ")
A40: 16 | C40: =IFERROR(VLOOKUP(B40,'Lista de Productos'!A:B,2,FALSE)," ") | D40: =IFERROR(VLOOKUP(B40,Tabla_Lista_de_productoss[],5,0),"") | I40: =IFERROR(FIXED(((1-((1-F40%)*(1-G40%)*(1-H40%)))*100),2)," ") -> 0.00 | J40: =IFERROR((E40*(D40*(1-I40%)))," ") | N40: =IFERROR(VLOOKUP(B40,'Lista de Productos'!A:D,4,FALSE)," ") | O40: =IFERROR(VLOOKUP(B40,'Lista de Productos'!A:C,3,FALSE)," ")
A41: 17 | C41: =IFERROR(VLOOKUP(B41,'Lista de Productos'!A:B,2,FALSE)," ") | D41: =IFERROR(VLOOKUP(B41,Tabla_Lista_de_productoss[],5,0),"") | I41: =IFERROR(FIXED(((1-((1-F41%)*(1-G41%)*(1-H41%)))*100),2)," ") -> 0.00 | J41: =IFERROR((E41*(D41*(1-I41%)))," ") | N41: =IFERROR(VLOOKUP(B41,'Lista de Productos'!A:D,4,FALSE)," ") | O41: =IFERROR(VLOOKUP(B41,'Lista de Productos'!A:C,3,FALSE)," ")
A42: 18 | C42: =IFERROR(VLOOKUP(B42,'Lista de Productos'!A:B,2,FALSE)," ") | D42: =IFERROR(VLOOKUP(B42,Tabla_Lista_de_productoss[],5,0),"") | I42: =IFERROR(FIXED(((1-((1-F42%)*(1-G42%)*(1-H42%)))*100),2)," ") -> 0.00 | J42: =IFERROR((E42*(D42*(1-I42%)))," ") | N42: =IFERROR(VLOOKUP(B42,'Lista de Productos'!A:D,4,FALSE)," ") | O42: =IFERROR(VLOOKUP(B42,'Lista de Productos'!A:C,3,FALSE)," ")
A43: 19 | C43: =IFERROR(VLOOKUP(B43,'Lista de Productos'!A:B,2,FALSE)," ") | D43: =IFERROR(VLOOKUP(B43,Tabla_Lista_de_productoss[],5,0),"") | I43: =IFERROR(FIXED(((1-((1-F43%)*(1-G43%)*(1-H43%)))*100),2)," ") -> 0.00 | J43: =IFERROR((E43*(D43*(1-I43%)))," ") | N43: =IFERROR(VLOOKUP(B43,'Lista de Productos'!A:D,4,FALSE)," ") | O43: =IFERROR(VLOOKUP(B43,'Lista de Productos'!A:C,3,FALSE)," ")
A44: 20 | C44: =IFERROR(VLOOKUP(B44,'Lista de Productos'!A:B,2,FALSE)," ") | D44: =IFERROR(VLOOKUP(B44,Tabla_Lista_de_productoss[],5,0),"") | I44: =IFERROR(FIXED(((1-((1-F44%)*(1-G44%)*(1-H44%)))*100),2)," ") -> 0.00 | J44: =IFERROR((E44*(D44*(1-I44%)))," ") | N44: =IFERROR(VLOOKUP(B44,'Lista de Productos'!A:D,4,FALSE)," ") | O44: =IFERROR(VLOOKUP(B44,'Lista de Productos'!A:C,3,FALSE)," ")
A45: 21 | C45: =IFERROR(VLOOKUP(B45,'Lista de Productos'!A:B,2,FALSE)," ") | D45: =IFERROR(VLOOKUP(B45,Tabla_Lista_de_productoss[],5,0),"") | I45: =IFERROR(FIXED(((1-((1-F45%)*(1-G45%)*(1-H45%)))*100),2)," ") -> 0.00 | J45: =IFERROR((E45*(D45*(1-I45%)))," ") | N45: =IFERROR(VLOOKUP(B45,'Lista de Productos'!A:D,4,FALSE)," ") | O45: =IFERROR(VLOOKUP(B45,'Lista de Productos'!A:C,3,FALSE)," ")
A46: 22 | C46: =IFERROR(VLOOKUP(B46,'Lista de Productos'!A:B,2,FALSE)," ") | D46: =IFERROR(VLOOKUP(B46,Tabla_Lista_de_productoss[],5,0),"") | I46: =IFERROR(FIXED(((1-((1-F46%)*(1-G46%)*(1-H46%)))*100),2)," ") -> 0.00 | J46: =IFERROR((E46*(D46*(1-I46%)))," ") | N46: =IFERROR(VLOOKUP(B46,'Lista de Productos'!A:D,4,FALSE)," ") | O46: =IFERROR(VLOOKUP(B46,'Lista de Productos'!A:C,3,FALSE)," ")
...

Sheet PROMO
A1: COD. ARTICULO | B1: DESCRIPCION | C1: LISTA GENERAL | D1: FAMILIA SAP | E1: Column5 | F1: Column6
A2: DLM330Z-3.0 | B2: DLM330Z(x1) + 632G12-3(x1) + 630718-5(x1) | C2: 1185.5932 | D2: PROMOCIONES | F2: OPELXT MG LISTA 2
A3: DLM330Z-6.0 | B3: DLM330Z(x1) + 632F69-8(x1) + 630718-5(x1) | C3: 1312.7119 | D3: PROMOCIONES
A4: DUR192LSF-3.0 | B4: DUR192LSF(x1) | C4: 888.98305 | D4: PROMOCIONES
A5: DUC101RF01-3.0 | B5: DUC101RF01(x1) | C5: 846.61017 | D5: PROMOCIONES
A6: DUC101Z01-6.0 | B6: DUC101Z01(x1) + 632F69-8(x1) + 630718-5(x1) | C6: 973.72881 | D6: PROMOCIONES
A7: DUC254Z-3.0 | B7: DUC254Z(x1) + 632G12-3(x1) + 630718-5(x1) | C7: 1185.5932 | D7: PROMOCIONES
A8: DUC254Z-6.0 | B8: DUC254Z(x1) + 632F69-8(x1) + 630718-5(x1) | C8: 1312.7119 | D8: PROMOCIONES
A9: DUC407ZX3-3.0 | B9: DUC407ZX3(x1) + 632G12-3(x1) + 630718-5(x1) | C9: 1143.2203 | D9: PROMOCIONES
A10: DUC407ZX3-6.0 | B10: DUC407ZX3(x1) + 632F69-8(x1) + 630718-5(x1) | C10: 1270.339 | D10: PROMOCIONES
A11: DUH606Z-3.0 | B11: DUH606Z(x1) + 632G12-3(x1) + 630718-5(x1) | C11: 1100.8475 | D11: PROMOCIONES
A12: DUH606Z-6.0 | B12: DUH606Z(x1) + 632F69-8(x1) + 630718-5(x1) | C12: 1227.9661 | D12: PROMOCIONES
A13: DUN461WZ-3.0 | B13: DUN461WZ(x1) + 632G12-3(x1) + 630718-5(x1) | C13: 829.66102 | D13: PROMOCIONES
A14: DUN461WZ-6.0 | B14: DUN461WZ(x1) + 632F69-8(x1) + 630718-5(x1) | C14: 1016.1017 | D14: PROMOCIONES
... A56: DUV320Z-6.0 | B56: DUV320Z(x1) + 632F69-8(x1) + 630718-5(x1) | C56: 1312.7119 | D56: PROMOCIONES
A57: CL117FDX1-B | B57: CL117FDX1(x1) | C57: 338.14 | D57: PROMOCIONES | F57: BIRUMEN LISTA 2
A58: CL117FDX4-B | B58: CL117FDX4(x1) | C58: 338.14 | D58: PROMOCIONES
A59: CL117FDX7-B | B59: CL117FDX7(x1) | C59: 338.14 | D59: PROMOCIONES
A60: CL108FDZW-2.0 | B60: CL108FDZW(x1) + 632F59-1(x1) + 630996-7(x1) | C60: 422.88 | D60: PROMOCIONES
A61: DCL181FZW-3.0 | B61: DCL181FZW(x1) + 632G12-3(x1) + 630718-5(x1) | C61: 507.63 | D61: PROMOCIONES
A62: DCL181FZW-6.0 | B62: DCL181FZW(x1) + 632F69-8(x1) + 630718-5(x1) | C62: 592.37 | D62: PROMOCIONES
A63: DCL283FZB-3.0 | B63: DCL283FZB(x1) + 632G12-3(x1) + 630718-5(x1) | C63: 634.75 | D63: PROMOCIONES
A64: DCL283FZB-6.0 | B64: DCL283FZB(x1) + 632F69-8(x1) + 630718-5(x1) | C64: 719.49 | D64: PROMOCIONES
A65: DCL283FZW-3.0 | B65: DCL283FZW(x1) + 632G12-3(x1) + 630718-5(x1) | C65: 634.75 | D65: PROMOCIONES
A66: DCL283FZW-6.0 | B66: DCL283FZW(x1) + 632F69-8(x1) + 630718-5(x1) | C66: 719.49 | D66: PROMOCIONES
A67: DCL286FZB-3.0 | B67: DCL286FZB(x1) + 632G12-3(x1) + 630718-5(x1) | C67: 677.12 | D67: PROMOCIONES
A68: DCL286FZB-6.0 | B68: DCL286FZB(x1) + 632F69-8(x1) + 630718-5(x1) | C68: 761.86 | D68: PROMOCIONES
A69: DCL286FZW-3.0 | B69: DCL286FZW(x1) + 632G12-3(x1) + 630718-5(x1) | C69: 677.12 | D69: PROMOCIONES
... A109: PS001GZ-4.0F | B109: PS001GZ(x1) + 632T21-0(x1) + 630B63-0(x1) | C109: 2795.76 | D109: PROMOCIONES
A110: LM004GZ-5.0 | B110: LM004GZ(x1) + 632R45-4(x1) + 630B63-0(x1) | C110: 2202.5424 | D110: PROMOCIONES | F110: XGT LISTA 2
A111: LM004GZ-8.0 | B111: LM004GZ(x1) + 632S90-5(x1) + 630B63-0(x1) | C111: 2456.7797 | D111: PROMOCIONES
A112: LM002GZ-5.0 | B112: LM002GZ(x1) + 632R45-4(x2) + 630C46-6(x1) | C112: 5083.8983 | D112: PROMOCIONES
A113: LM002GZ-8.0 | B113: LM002GZ(x1) + 632S90-5(x2) + 630C46-6(x1) | C113: 5507.6271 | D113: PROMOCIONES
A114: UR002GZ-5.0 | B114: UR002GZ(x1) + 632R45-4(x1) + 630B63-0(x1) | C114: 2202.5424 | D114: PROMOCIONES
A115: UR002GZ-8.0 | B115: UR002GZ(x1) + 632S90-5(x1) + 630B63-0(x1) | C115: 2456.7797 | D115: PROMOCIONES
A116: UR016GZ-5.0 | B116: UR016GZ(x1) + 632R45-4(x1) + 630B63-0(x1) | C116: 2287.2881 | D116: PROMOCIONES
A117: UR016GZ-8.0 | B117: UR016GZ(x1) + 632S90-5(x1) + 630B63-0(x1) | C117: 2541.5254 | D117: PROMOCIONES
A118: UR006GZ02-5.0 | B118: UR006GZ02(x1) + 632R45-4(x1) + 630B63-0(x1) | C118: 2372.0339 | D118: PROMOCIONES
A119: UR006GZ02-8.0 | B119: UR006GZ02(x1) + 632S90-5(x1) + 630B63-0(x1) | C119: 2626.2712 | D119: PROMOCIONES
A120: UR013GZ03-5.0 | B120: UR013GZ03(x1) + 632R45-4(x1) + 630B63-0(x1) | C120: 2795.7627 | D120: PROMOCIONES
...

Sheet Lista de Productos
A1: COD. ARTICULO | B1: DESCRIPCION | C1: FAMILIA SAP | D1: Status | E1: LISTA GENERAL
A2: 042040-2A | B2: PAQUETE DE GRASA 500 G. PARA MODELOS HR52 | C2: ACCESORIOS | D2: Verde | E2: 110.3
A3: 103154900 | B3: WIDE REFLECTOR NOZZLE 75MM | C3: ACCESORIOS | D3: Morado | E3: 34.17
A4: 103155000 | B4: WIDE REFLECTOR NOZZLE PB | C4: ACCESORIOS | D4: Morado | E4: 50.47
A5: 103155100 | B5: BOQUILLA DE REDUCCION 9mm | C5: ACCESORIOS | D5: Amarillo | E5: 29.4
A6: 110751-A | B6: ""BOQUILLA 1.3/4""x 3/16"" PVC" | C6: ACCESORIOS | D6: Morado | E6: 122.34
A7: 122256-6 | B7: PORTA GUIA CIRCULAR 3612-BR | C7: ACCESORIOS | D7: Rojo | E7: 113.4
A8: 122291-4 | B8: Boquilla Tipo T para Alfombra (Crema) | C8: ACCESORIOS | D8: Rojo | E8: 69.3
A9: 122296-4 | B9: BOLSA PARA POLVO P/9924DB | C9: ACCESORIOS | D9: Amarillo | E9: 71.25
A10: 122321-1 | B10: BOLSA PARA POLVO P/4014N | C10: ACCESORIOS | D10: Rojo | E10: 11.24
A11: 122335-0 | B11: Boquilla Tipo T Húmedo Marfil (38 mm) | C11: ACCESORIOS | D11: Morado | E11: 82.47
A12: 122343-1 | B12: GUIA RECORTADORA P/3606 | C12: ACCESORIOS | D12: Morado | E12: 134.82
A13: 122402-1 | B13: BOLSA PARA POLVO | C13: ACCESORIOS | D13: Amarillo | E13: 196.61
... A5838: ZM00000228 | B5838: ACCESORIO PARA CRIMPADORA DTC301/302 MEDIDA CABLE K34 | C5838: ACCESORIOS | D5838: Morado | E5838: 1267.28
A5839: LM004GZ-5.0X | B5839: LM004GZ(x1) + 632X12-5(x1) + 630B63-0(x1) | C5839: PROMOCIONES | E5839: 2202.5424
A5840: LM004GZ-8.0X | B5840: LM004GZ(x1) + 632X21-4(x1) + 630B63-0(x1) | C5840: PROMOCIONES | E5840: 2456.7797
A5841: LM002GZ-5.0X | B5841: LM002GZ(x1) + 632X12-5(x2) + 630C46-6(x1) | C5841: PROMOCIONES | E5841: 5083.8983
A5842: LM002GZ-8.0X | B5842: LM002GZ(x1) + 632X21-4(x2) + 630C46-6(x1) | C5842: PROMOCIONES | E5842: 5507.6271
A5843: UR002GZ-5.0X | B5843: UR002GZ(x1) + 632X12-5(x1) + 630B63-0(x1) | C5843: PROMOCIONES | E5843: 2202.5424
A5844: UR002GZ-8.0X | B5844: UR002GZ(x1) + 632X21-4(x1) + 630B63-0(x1) | C5844: PROMOCIONES | E5844: 2456.7797
A5845: UR016GZ-5.0X | B5845: UR016GZ(x1) + 632X12-5(x1) + 630B63-0(x1) | C5845: PROMOCIONES | E5845: 2287.2881
A5846: UR006GZ02-5.0X | B5846: UR006GZ02(x1) + 632X12-5(x1) + 630B63-0(x1) | C5846: PROMOCIONES | E5846: 2372.0339
A5847: UR006GZ02-8.0X | B5847: UR006GZ02(x1) + 632X21-4(x1) + 630B63-0(x1) | C5847: PROMOCIONES | E5847: 2626.2712
A5848: UR013GZ03-5.0X | B5848: UR013GZ03(x1) + 632X12-5(x1) + 630B63-0(x1) | C5848: PROMOCIONES | E5848: 2795.7627
A5849: UR013GZ03-8.0X | B5849: UR013GZ03(x1) + 632X21-4(x1) + 630B63-0(x1) | C5849: PROMOCIONES | E5849: 3050
A5850: UR012GZ02-8.0X | B5850: UR012GZ02(x1) + 632X21-4(x2) + 630C46-6(x1) | C5850: PROMOCIONES | E5850: 4236.4407
... A6172: VC013GLZ-LQ2 | B6172: VC013GLZ(x1) + BO003CGZ(x1) + 632X12-5(x1)+ 630C66-0(x1) | C6172: PROMOCIONES | E6172: 1677.2034
